Workbook

Sheet Batch summary
A2: Full SAR batch register
A6: Group | B6: Batch | C6: Area | D6: Scenes | E6: Closest optical gap (h) | F6: Acquisition span (days) | G6: Ubuntu | H6: Drive | I6: Transferred | J6: Digitised | K6: Transferred back | L6: Extracted | M6: Notes
A7: Global MERIA | B7: meria_honduras_2017_oct17 | C7: Bay Islands of Honduras | D7: 1 | E7: 3.98 | F7: 0 | I7: =COUNTIFS(Scenes!$B$7:$B$142,$B7,Scenes!$L$7:$L$142,"Done") -> 0 | J7: =COUNTIFS(Scenes!$B$7:$B$142,$B7,Scenes!$M$7:$M$142,"Done") -> 0 | K7: =COUNTIFS(Scenes!$B$7:$B$142,$B7,Scenes!$N$7:$N$142,"Done") -> 0 | L7: =COUNTIFS(Scenes!$B$7:$B$142,$B7,Scenes!$O$7:$O$142,"Done") -> 0 | M7: To do once the full scene processing is done for the palma area and then for Ghana as well.
A8: Global MERIA | B8: meria_palma_2018_oct12 | C8: Palma de Mallorca | D8: 2 | E8: 4.35 | F8: 0.49542824 | I8: =COUNTIFS(Scenes!$B$7:$B$142,$B8,Scenes!$L$7:$L$142,"Done") -> 0 | J8: =COUNTIFS(Scenes!$B$7:$B$142,$B8,Scenes!$M$7:$M$142,"Done") -> 0 | K8: =COUNTIFS(Scenes!$B$7:$B$142,$B8,Scenes!$N$7:$N$142,"Done") -> 0 | L8: =COUNTIFS(Scenes!$B$7:$B$142,$B8,Scenes!$O$7:$O$142,"Done") -> 0
A9: Global MERIA | B9: meria_bay_islands_2018_oct24_25 | C9: Bay Islands (16PDC and 16PCC) | D9: 3 | E9: 4.405 | F9: 0.52025463 | I9: 0 | J9: =COUNTIFS(Scenes!$B$7:$B$142,$B9,Scenes!$M$7:$M$142,"Done") -> 0 | K9: =COUNTIFS(Scenes!$B$7:$B$142,$B9,Scenes!$N$7:$N$142,"Done") -> 0 | L9: =COUNTIFS(Scenes!$B$7:$B$142,$B9,Scenes!$O$7:$O$142,"Done") -> 0
A10: Global MERIA | B10: meria_ghana_2018_oct30_nov05 | C10: Ghana | D10: 2 | E10: 15.69 | F10: 5.9995255 | I10: =COUNTIFS(Scenes!$B$7:$B$142,$B10,Scenes!$L$7:$L$142,"Done") -> 0 | J10: =COUNTIFS(Scenes!$B$7:$B$142,$B10,Scenes!$M$7:$M$142,"Done") -> 0 | K10: =COUNTIFS(Scenes!$B$7:$B$142,$B10,Scenes!$N$7:$N$142,"Done") -> 0 | L10: =COUNTIFS(Scenes!$B$7:$B$142,$B10,Scenes!$O$7:$O$142,"Done") -> 0
A11: Global MERIA | B11: meria_ghana_2018_oct25_31 | C11: Ghana | D11: 2 | E11: 15.84 | F11: 5.9994792 | I11: =COUNTIFS(Scenes!$B$7:$B$142,$B11,Scenes!$L$7:$L$142,"Done") -> 0 | J11: =COUNTIFS(Scenes!$B$7:$B$142,$B11,Scenes!$M$7:$M$142,"Done") -> 0 | K11: =COUNTIFS(Scenes!$B$7:$B$142,$B11,Scenes!$N$7:$N$142,"Done") -> 0 | L11: =COUNTIFS(Scenes!$B$7:$B$142,$B11,Scenes!$O$7:$O$142,"Done") -> 0
A12: Global MERIA | B12: meria_ghana_2018_oct18_24 | C12: Ghana | D12: 2 | E12: 39.7 | F12: 5.9995255 | I12: =COUNTIFS(Scenes!$B$7:$B$142,$B12,Scenes!$L$7:$L$142,"Done") -> 0 | J12: =COUNTIFS(Scenes!$B$7:$B$142,$B12,Scenes!$M$7:$M$142,"Done") -> 0 | K12: =COUNTIFS(Scenes!$B$7:$B$142,$B12,Scenes!$N$7:$N$142,"Done") -> 0 | L12: =COUNTIFS(Scenes!$B$7:$B$142,$B12,Scenes!$O$7:$O$142,"Done") -> 0
A13: Global MERIA | B13: meria_honduras_2017_oct05 | C13: Bay Islands of Honduras | D13: 1 | E13: 170.6 | F13: 0 | I13: =COUNTIFS(Scenes!$B$7:$B$142,$B13,Scenes!$L$7:$L$142,"Done") -> 0 | J13: =COUNTIFS(Scenes!$B$7:$B$142,$B13,Scenes!$M$7:$M$142,"Done") -> 0 | K13: =COUNTIFS(Scenes!$B$7:$B$142,$B13,Scenes!$N$7:$N$142,"Done") -> 0 | L13: =COUNTIFS(Scenes!$B$7:$B$142,$B13,Scenes!$O$7:$O$142,"Done") -> 0
A14: Global MERIA | B14: meria_honduras_2017_oct29 | C14: Bay Islands of Honduras | D14: 1 | E14: 284.02 | F14: 0 | I14: =COUNTIFS(Scenes!$B$7:$B$142,$B14,Scenes!$L$7:$L$142,"Done") -> 0 | J14: =COUNTIFS(Scenes!$B$7:$B$142,$B14,Scenes!$M$7:$M$142,"Done") -> 0 | K14: =COUNTIFS(Scenes!$B$7:$B$142,$B14,Scenes!$N$7:$N$142,"Done") -> 0 | L14: =COUNTIFS(Scenes!$B$7:$B$142,$B14,Scenes!$O$7:$O$142,"Done") -> 0
A15: MARIDA | B15: marida_16pcc_20180830_05 | C15: 16PCC | D15: 2 | E15: 4.372 | F15: 0.00028935185 | G15: Y | H15: Y | I15: Y | J15: Y | K15: =COUNTIFS(Scenes!$B$7:$B$142,$B15,Scenes!$N$7:$N$142,"Done") -> 0 | L15: =COUNTIFS(Scenes!$B$7:$B$142,$B15,Scenes!$O$7:$O$142,"Done") -> 0
A16: MARIDA | B16: marida_51pts_20160716_01 | C16: 51PTS | D16: 1 | E16: 4.495 | F16: 0 | G16: Y | H16: Y | I16: Y | J16: Y | K16: P | L16: =COUNTIFS(Scenes!$B$7:$B$142,$B16,Scenes!$O$7:$O$142,"Done") -> 0
A17: MARIDA | B17: marida_18qyf_20210123_20210125_08 | C17: 18QYF | D17: 2 | E17: 4.653 | F17: 2.5096875 | G17: Y | H17: Y | I17: Y | J17: Y | K17: P | L17: =COUNTIFS(Scenes!$B$7:$B$142,$B17,Scenes!$O$7:$O$142,"Done") -> 0
A18: MARIDA | B18: marida_30vwh_20180419_20180420_01 | C18: 30VWH | D18: 2 | E18: 6.491 | F18: 0.99491898 | G18: Y | H18: Y | I18: y | J18: Y | K18: =COUNTIFS(Scenes!$B$7:$B$142,$B18,Scenes!$N$7:$N$142,"Done") -> 0 | L18: =COUNTIFS(Scenes!$B$7:$B$142,$B18,Scenes!$O$7:$O$142,"Done") -> 0
A19: MARIDA | B19: marida_18qyf_20200319_01 | C19: 18QYF | D19: 1 | E19: 7.577 | F19: 0 | G19: Y | H19: Y | I19: Y | J19: 0 | K19: =COUNTIFS(Scenes!$B$7:$B$142,$B19,Scenes!$N$7:$N$142,"Done") -> 0 | L19: =COUNTIFS(Scenes!$B$7:$B$142,$B19,Scenes!$O$7:$O$142,"Done") -> 0
A20: MARIDA | B20: marida_18qyf_20200915_02 | C20: 18QYF | D20: 1 | E20: 7.58 | F20: 0 | G20: Y | H20: Y | I20: Y | J20: Y | K20: =COUNTIFS(Scenes!$B$7:$B$142,$B20,Scenes!$N$7:$N$142,"Done") -> 0 | L20: =COUNTIFS(Scenes!$B$7:$B$142,$B20,Scenes!$O$7:$O$142,"Done") -> 0
A21: MARIDA | B21: marida_48pzc_20191124_01 | C21: 48PZC | D21: 1 | E21: 7.765 | F21: 0 | G21: Y | H21: Y | I21: Y | J21: Y | K21: =COUNTIFS(Scenes!$B$7:$B$142,$B21,Scenes!$N$7:$N$142,"Done") -> 0 | L21: =COUNTIFS(Scenes!$B$7:$B$142,$B21,Scenes!$O$7:$O$142,"Done") -> 0
A22: MARIDA | B22: marida_16pcc_20170831_03 | C22: 16PCC | D22: 1 | E22: 7.955 | F22: 0 | G22: Y | H22: Y | I22: y | J22: =COUNTIFS(Scenes!$B$7:$B$142,$B22,Scenes!$M$7:$M$142,"Done") -> 0 | K22: =COUNTIFS(Scenes!$B$7:$B$142,$B22,Scenes!$N$7:$N$142,"Done") -> 0 | L22: =COUNTIFS(Scenes!$B$7:$B$142,$B22,Scenes!$O$7:$O$142,"Done") -> 0
A23: MARIDA | B23: marida_18qyg_20200305_20200307_01 | C23: 18QYG | D23: 3 | E23: 11.022 | F23: 2.5099884 | G23: Y | H23: Y | I23: Y | J23: =COUNTIFS(Scenes!$B$7:$B$142,$B23,Scenes!$M$7:$M$142,"Done") -> 0 | K23: =COUNTIFS(Scenes!$B$7:$B$142,$B23,Scenes!$N$7:$N$142,"Done") -> 0 | L23: =COUNTIFS(Scenes!$B$7:$B$142,$B23,Scenes!$O$7:$O$142,"Done") -> 0
A24: MARIDA | B24: marida_18qyg_20200307_02 | C24: 18QYG | D24: 1 | E24: 11.029 | F24: 0 | G24: Y | H24: Y | I24: 0 | J24: =COUNTIFS(Scenes!$B$7:$B$142,$B24,Scenes!$M$7:$M$142,"Done") -> 0 | K24: =COUNTIFS(Scenes!$B$7:$B$142,$B24,Scenes!$N$7:$N$142,"Done") -> 0 | L24: =COUNTIFS(Scenes!$B$7:$B$142,$B24,Scenes!$O$7:$O$142,"Done") -> 0
A25: MARIDA | B25: marida_52sdd_20181006_01 | C25: 52SDD | D25: 1 | E25: 14.602 | F25: 0 | G25: Y | H25: Y | I25: =COUNTIFS(Scenes!$B$7:$B$142,$B25,Scenes!$L$7:$L$142,"Done") -> 0 | J25: =COUNTIFS(Scenes!$B$7:$B$142,$B25,Scenes!$M$7:$M$142,"Done") -> 0 | K25: =COUNTIFS(Scenes!$B$7:$B$142,$B25,Scenes!$N$7:$N$142,"Done") -> 0 | L25: =COUNTIFS(Scenes!$B$7:$B$142,$B25,Scenes!$O$7:$O$142,"Done") -> 0
A26: MARIDA | B26: marida_16pec_20190111_03 | C26: 16PEC | D26: 2 | E26: 16.302 | F26: 0.00028935185 | G26: Y | H26: y | I26: =COUNTIFS(Scenes!$B$7:$B$142,$B26,Scenes!$L$7:$L$142,"Done") -> 0 | J26: =COUNTIFS(Scenes!$B$7:$B$142,$B26,Scenes!$M$7:$M$142,"Done") -> 0 | K26: =COUNTIFS(Scenes!$B$7:$B$142,$B26,Scenes!$N$7:$N$142,"Done") -> 0 | L26: =COUNTIFS(Scenes!$B$7:$B$142,$B26,Scenes!$O$7:$O$142,"Done") -> 0
A27: MARIDA | B27: marida_16qed_20190128_01 | C27: 16QED | D27: 1 | E27: 19.359 | F27: 0 | G27: Y | H27: y | I27: =COUNTIFS(Scenes!$B$7:$B$142,$B27,Scenes!$L$7:$L$142,"Done") -> 0 | J27: =COUNTIFS(Scenes!$B$7:$B$142,$B27,Scenes!$M$7:$M$142,"Done") -> 0 | K27: =COUNTIFS(Scenes!$B$7:$B$142,$B27,Scenes!$N$7:$N$142,"Done") -> 0 | L27: =COUNTIFS(Scenes!$B$7:$B$142,$B27,Scenes!$O$7:$O$142,"Done") -> 0
A28: MARIDA | B28: marida_16pcc_20200924_08 | C28: 16PCC | D28: 2 | E28: 19.593 | F28: 0.00027777778 | G28: Y | I28: =COUNTIFS(Scenes!$B$7:$B$142,$B28,Scenes!$L$7:$L$142,"Done") -> 0 | J28: =COUNTIFS(Scenes!$B$7:$B$142,$B28,Scenes!$M$7:$M$142,"Done") -> 0 | K28: =COUNTIFS(Scenes!$B$7:$B$142,$B28,Scenes!$N$7:$N$142,"Done") -> 0 | L28: =COUNTIFS(Scenes!$B$7:$B$142,$B28,Scenes!$O$7:$O$142,"Done") -> 0
A29: MARIDA | B29: marida_50llr_20180302_20180305_01 | C29: 50LLR | D29: 2 | E29: 28.395 | F29: 2.5339468 | I29: =COUNTIFS(Scenes!$B$7:$B$142,$B29,Scenes!$L$7:$L$142,"Done") -> 0 | J29: =COUNTIFS(Scenes!$B$7:$B$142,$B29,Scenes!$M$7:$M$142,"Done") -> 0 | K29: =COUNTIFS(Scenes!$B$7:$B$142,$B29,Scenes!$N$7:$N$142,"Done") -> 0 | L29: =COUNTIFS(Scenes!$B$7:$B$142,$B29,Scenes!$O$7:$O$142,"Done") -> 0
A30: MARIDA | B30: marida_16pdc_20180918_01 | C30: 16PDC | D30: 1 | E30: 28.537 | F30: 0 | I30: =COUNTIFS(Scenes!$B$7:$B$142,$B30,Scenes!$L$7:$L$142,"Done") -> 0 | J30: =COUNTIFS(Scenes!$B$7:$B$142,$B30,Scenes!$M$7:$M$142,"Done") -> 0 | K30: =COUNTIFS(Scenes!$B$7:$B$142,$B30,Scenes!$N$7:$N$142,"Done") -> 0 | L30: =COUNTIFS(Scenes!$B$7:$B$142,$B30,Scenes!$O$7:$O$142,"Done") -> 0
A31: MARIDA | B31: marida_18qyf_20201213_05 | C31: 18QYF | D31: 2 | E31: 28.786 | F31: 0.00028935185 | I31: =COUNTIFS(Scenes!$B$7:$B$142,$B31,Scenes!$L$7:$L$142,"Done") -> 0 | J31: =COUNTIFS(Scenes!$B$7:$B$142,$B31,Scenes!$M$7:$M$142,"Done") -> 0 | K31: =COUNTIFS(Scenes!$B$7:$B$142,$B31,Scenes!$N$7:$N$142,"Done") -> 0 | L31: =COUNTIFS(Scenes!$B$7:$B$142,$B31,Scenes!$O$7:$O$142,"Done") -> 0
A32: MARIDA | B32: marida_18qyf_20201021_03 | C32: 18QYF | D32: 1 | E32: 31.581 | F32: 0 | I32: =COUNTIFS(Scenes!$B$7:$B$142,$B32,Scenes!$L$7:$L$142,"Done") -> 0 | J32: =COUNTIFS(Scenes!$B$7:$B$142,$B32,Scenes!$M$7:$M$142,"Done") -> 0 | K32: =COUNTIFS(Scenes!$B$7:$B$142,$B32,Scenes!$N$7:$N$142,"Done") -> 0 | L32: =COUNTIFS(Scenes!$B$7:$B$142,$B32,Scenes!$O$7:$O$142,"Done") -> 0
A33: MARIDA | B33: marida_48myu_20171203_20171207_01 | C33: 48MYU | D33: 3 | E33: 32.234 | F33: 3.5290394 | I33: =COUNTIFS(Scenes!$B$7:$B$142,$B33,Scenes!$L$7:$L$142,"Done") -> 0 | J33: =COUNTIFS(Scenes!$B$7:$B$142,$B33,Scenes!$M$7:$M$142,"Done") -> 0 | K33: =COUNTIFS(Scenes!$B$7:$B$142,$B33,Scenes!$N$7:$N$142,"Done") -> 0 | L33: =COUNTIFS(Scenes!$B$7:$B$142,$B33,Scenes!$O$7:$O$142,"Done") -> 0
A34: MARIDA | B34: marida_51pts_20190516_02 | C34: 51PTS | D34: 2 | E34: 40.167 | F34: 0.00027777778 | L34: =COUNTIFS(Scenes!$B$7:$B$142,$B34,Scenes!$O$7:$O$142,"Done") -> 0
A35: MARIDA | B35: marida_16pdc_20200926_03 | C35: 16PDC | D35: 2 | E35: 40.187 | F35: 0.00028935185 | I35: =COUNTIFS(Scenes!$B$7:$B$142,$B35,Scenes!$L$7:$L$142,"Done") -> 0 | J35: =COUNTIFS(Scenes!$B$7:$B$142,$B35,Scenes!$M$7:$M$142,"Done") -> 0 | K35: =COUNTIFS(Scenes!$B$7:$B$142,$B35,Scenes!$N$7:$N$142,"Done") -> 0 | L35: =COUNTIFS(Scenes!$B$7:$B$142,$B35,Scenes!$O$7:$O$142,"Done") -> 0
A36: MARIDA | B36: marida_18qyf_20210101_07 | C36: 18QYF | D36: 1 | E36: 40.421 | F36: 0 | I36: =COUNTIFS(Scenes!$B$7:$B$142,$B36,Scenes!$L$7:$L$142,"Done") -> 0 | J36: =COUNTIFS(Scenes!$B$7:$B$142,$B36,Scenes!$M$7:$M$142,"Done") -> 0 | K36: =COUNTIFS(Scenes!$B$7:$B$142,$B36,Scenes!$N$7:$N$142,"Done") -> 0 | L36: =COUNTIFS(Scenes!$B$7:$B$142,$B36,Scenes!$O$7:$O$142,"Done") -> 0
A37: MARIDA | B37: marida_18qyf_20201220_06 | C37: 18QYF | D37: 1 | E37: 40.581 | F37: 0 | I37: =COUNTIFS(Scenes!$B$7:$B$142,$B37,Scenes!$L$7:$L$142,"Done") -> 0 | J37: =COUNTIFS(Scenes!$B$7:$B$142,$B37,Scenes!$M$7:$M$142,"Done") -> 0 | K37: =COUNTIFS(Scenes!$B$7:$B$142,$B37,Scenes!$N$7:$N$142,"Done") -> 0 | L37: =COUNTIFS(Scenes!$B$7:$B$142,$B37,Scenes!$O$7:$O$142,"Done") -> 0
A38: MARIDA | B38: marida_16pcc_20190906_07 | C38: 16PCC | D38: 1 | E38: 43.62 | F38: 0 | I38: =COUNTIFS(Scenes!$B$7:$B$142,$B38,Scenes!$L$7:$L$142,"Done") -> 0 | J38: =COUNTIFS(Scenes!$B$7:$B$142,$B38,Scenes!$M$7:$M$142,"Done") -> 0 | K38: =COUNTIFS(Scenes!$B$7:$B$142,$B38,Scenes!$N$7:$N$142,"Done") -> 0 | L38: =COUNTIFS(Scenes!$B$7:$B$142,$B38,Scenes!$O$7:$O$142,"Done") -> 0
A39: MARIDA | B39: marida_16pec_20180305_20180310_02 | C39: 16PEC | D39: 3 | E39: 47.618 | F39: 4.4856134 | I39: =COUNTIFS(Scenes!$B$7:$B$142,$B39,Scenes!$L$7:$L$142,"Done") -> 0 | J39: =COUNTIFS(Scenes!$B$7:$B$142,$B39,Scenes!$M$7:$M$142,"Done") -> 0 | K39: =COUNTIFS(Scenes!$B$7:$B$142,$B39,Scenes!$N$7:$N$142,"Done") -> 0 | L39: =COUNTIFS(Scenes!$B$7:$B$142,$B39,Scenes!$O$7:$O$142,"Done") -> 0
A40: MARIDA | B40: marida_16pcc_20180219_04 | C40: 16PCC | D40: 2 | E40: 52.464 | F40: 0.00028935185 | I40: =COUNTIFS(Scenes!$B$7:$B$142,$B40,Scenes!$L$7:$L$142,"Done") -> 0 | J40: =COUNTIFS(Scenes!$B$7:$B$142,$B40,Scenes!$M$7:$M$142,"Done") -> 0 | K40: =COUNTIFS(Scenes!$B$7:$B$142,$B40,Scenes!$N$7:$N$142,"Done") -> 0 | L40: =COUNTIFS(Scenes!$B$7:$B$142,$B40,Scenes!$O$7:$O$142,"Done") -> 0
A41: MARIDA | B41: marida_16pec_20180214_01 | C41: 16PEC | D41: 2 | E41: 52.602 | F41: 0.00032407407 | I41: =COUNTIFS(Scenes!$B$7:$B$142,$B41,Scenes!$L$7:$L$142,"Done") -> 0 | J41: =COUNTIFS(Scenes!$B$7:$B$142,$B41,Scenes!$M$7:$M$142,"Done") -> 0 | K41: =COUNTIFS(Scenes!$B$7:$B$142,$B41,Scenes!$N$7:$N$142,"Done") -> 0 | L41: =COUNTIFS(Scenes!$B$7:$B$142,$B41,Scenes!$O$7:$O$142,"Done") -> 0
A42: MARIDA | B42: marida_18qwf_20200324_01 | C42: 18QWF | D42: 1 | E42: 55.549 | F42: 0 | I42: =COUNTIFS(Scenes!$B$7:$B$142,$B42,Scenes!$L$7:$L$142,"Done") -> 0 | J42: =COUNTIFS(Scenes!$B$7:$B$142,$B42,Scenes!$M$7:$M$142,"Done") -> 0 | K42: =COUNTIFS(Scenes!$B$7:$B$142,$B42,Scenes!$N$7:$N$142,"Done") -> 0 | L42: =COUNTIFS(Scenes!$B$7:$B$142,$B42,Scenes!$O$7:$O$142,"Done") -> 0
A43: MARIDA | B43: marida_36jun_20190421_01 | C43: 36JUN | D43: 1 | E43: 62.975 | F43: 0 | I43: =COUNTIFS(Scenes!$B$7:$B$142,$B43,Scenes!$L$7:$L$142,"Done") -> 0 | J43: =COUNTIFS(Scenes!$B$7:$B$142,$B43,Scenes!$M$7:$M$142,"Done") -> 0 | K43: =COUNTIFS(Scenes!$B$7:$B$142,$B43,Scenes!$N$7:$N$142,"Done") -> 0 | L43: =COUNTIFS(Scenes!$B$7:$B$142,$B43,Scenes!$O$7:$O$142,"Done") -> 0
A44: MARIDA | B44: marida_16pdc_20181031_02 | C44: 16PDC | D44: 2 | E44: 64.269 | F44: 0.00028935185 | I44: =COUNTIFS(Scenes!$B$7:$B$142,$B44,Scenes!$L$7:$L$142,"Done") -> 0 | J44: =COUNTIFS(Scenes!$B$7:$B$142,$B44,Scenes!$M$7:$M$142,"Done") -> 0 | K44: =COUNTIFS(Scenes!$B$7:$B$142,$B44,Scenes!$N$7:$N$142,"Done") -> 0 | L44: =COUNTIFS(Scenes!$B$7:$B$142,$B44,Scenes!$O$7:$O$142,"Done") -> 0
...

Sheet Scenes
A2: Full SAR scene tracker
A4: Batches and scenes ordered by absolute optical-to-SAR time difference. Positive gap means SAR after optical. Blank status means unverified.
A6: Group | B6: Batch | C6: Area | D6: Acquired UTC | E6: Optical gap (h) | F6: Absolute gap (h) | G6: Reference source | H6: Optical reference ID | I6: SAR scene ID | J6: Linked sources | K6: Notes | L6: Transferred | M6: Digitised | N6: Transferred back | O6: Extracted
A7: Global MERIA | B7: meria_honduras_2017_oct17 | C7: Bay Islands of Honduras | D7: 2017-10-17 11:37:09 | E7: -3.98 | F7: 3.98 | G7: MERIA global | H7: 33a32832-fc41-4fdd-8c91-a41844fc1709 | I7: S1A_IW_SLC__1SDV_20171017T113709_20171017T113739_018852_01FD74_F01C | J7: MERIA global, NASA_PlanetScope
A8: Global MERIA | B8: meria_palma_2018_oct12 | C8: Palma de Mallorca | D8: 2018-10-12 05:44:31 | E8: -4.35 | F8: 4.35 | G8: MERIA global | H8: cabcd011-9d82-4124-9f9c-120bdc406cf3 | I8: S1B_IW_SLC__1SDV_20181012T054431_20181012T054458_013115_0183B4_07F8 | J8: MERIA global
A9: Global MERIA | B9: meria_palma_2018_oct12 | C9: Palma de Mallorca | D9: 2018-10-12 17:37:56 | E9: 7.54 | F9: 7.54 | G9: MERIA global | H9: cabcd011-9d82-4124-9f9c-120bdc406cf3 | I9: S1A_IW_SLC__1SDV_20181012T173756_20181012T173823_024106_02A2A6_DA1D | J9: MERIA global
A10: Global MERIA | B10: meria_bay_islands_2018_oct24_25 | C10: Bay Islands (16PDC and 16PCC) | D10: 2018-10-24 11:37:44 | E10: -4.405 | F10: 4.405 | G10: NASA_PlanetScope | H10: nasa_planetscope_20181024_160201_0f3b | I10: S1A_IW_SLC__1SDV_20181024T113744_20181024T113812_024277_02A836_EC6E | J10: MARIDA, NASA_PlanetScope | K10: 16PDC reference scene; separate from the 16PCC candidate points.
A11: Global MERIA | B11: meria_bay_islands_2018_oct24_25 | C11: Bay Islands (16PDC and 16PCC) | D11: 2018-10-24 11:37:16 | E11: -4.412 | F11: 4.412 | G11: NASA_PlanetScope | H11: nasa_planetscope_20181024_160201_0f3b | I11: S1A_IW_SLC__1SDV_20181024T113716_20181024T113746_024277_02A836_7D74 | J11: MARIDA, NASA_PlanetScope | K11: 16PDC reference scene; separate from the 16PCC candidate points.
A12: Global MERIA | B12: meria_bay_islands_2018_oct24_25 | C12: Bay Islands (16PDC and 16PCC) | D12: 2018-10-25 00:06:26 | E12: 8.073 | F12: 8.073 | G12: NASA_PlanetScope | H12: nasa_planetscope_20181024_160202_0f3b | I12: S1A_IW_SLC__1SDV_20181025T000626_20181025T000653_024285_02A86D_2AFA | J12: NASA_PlanetScope | K12: 16PCC: 85 added candidate points; verify valid SAR pixels.
A13: Global MERIA | B13: meria_ghana_2018_oct30_nov05 | C13: Ghana | D13: 2018-10-30 18:17:58 | E13: -15.69 | F13: 15.69 | G13: MERIA global | H13: 91ea9edc-67b4-4211-8532-35deec4a3148 | I13: S1A_IW_SLC__1SDV_20181030T181758_20181030T181828_024369_02AB27_32F5 | J13: Ghana_Drift, Jamila_Floating_Debris, MERIA global, NASA_PlanetScope
A14: Global MERIA | B14: meria_ghana_2018_oct30_nov05 | C14: Ghana | D14: 2018-11-05 18:17:17 | E14: 128.3 | F14: 128.3 | G14: MERIA global | H14: 91ea9edc-67b4-4211-8532-35deec4a3148 | I14: S1B_IW_SLC__1SDV_20181105T181717_20181105T181744_013473_018EDC_5E15 | J14: MERIA global
A15: Global MERIA | B15: meria_ghana_2018_oct25_31 | C15: Ghana | D15: 2018-10-25 18:09:53 | E15: -15.84 | F15: 15.84 | G15: MERIA global | H15: cd77705c-782d-5b99-935f-405bfd905cbf | I15: S1A_IW_SLC__1SDV_20181025T180953_20181025T181020_024296_02A8C4_97A2 | J15: Ghana_Drift, MERIA global
A16: Global MERIA | B16: meria_ghana_2018_oct25_31 | C16: Ghana | D16: 2018-10-31 18:09:08 | E16: 80.15 | F16: 80.15 | G16: MERIA global | H16: d9db6dd4-4db8-5723-96ba-57d182cda0b7_B | I16: S1B_IW_SLC__1SDV_20181031T180908_20181031T180935_013400_018CA3_F37E | J16: Ghana_Drift, Jamila_Floating_Debris, MERIA global
A17: Global MERIA | B17: meria_ghana_2018_oct18_24 | C17: Ghana | D17: 2018-10-18 18:17:58 | E17: -39.7 | F17: 39.7 | G17: MERIA global | H17: 57bbff03-21eb-54de-9d18-d8a65b256bd5 | I17: S1A_IW_SLC__1SDV_20181018T181758_20181018T181828_024194_02A587_7BBC | J17: Ghana_Drift, MERIA global
A18: Global MERIA | B18: meria_ghana_2018_oct18_24 | C18: Ghana | D18: 2018-10-24 18:17:17 | E18: -63.71 | F18: 63.71 | G18: MERIA global | H18: d918b4e9-16ac-5c30-830f-6945943e1d9e | I18: S1B_IW_SLC__1SDV_20181024T181717_20181024T181744_013298_01895D_793F | J18: Ghana_Drift, MERIA global
A19: Global MERIA | B19: meria_honduras_2017_oct05 | C19: Bay Islands of Honduras | D19: 2017-10-05 11:37:09 | E19: -170.6 | F19: 170.6 | G19: MERIA global | H19: 9e17ce98-9eeb-40f6-989e-894dc2be72ea | I19: S1A_IW_SLC__1SDV_20171005T113709_20171005T113739_018677_01F81E_9D47 | J19: MERIA global
A20: Global MERIA | B20: meria_honduras_2017_oct29 | C20: Bay Islands of Honduras | D20: 2017-10-29 11:37:10 | E20: 284.02 | F20: 284.02 | G20: MERIA global | H20: 33a32832-fc41-4fdd-8c91-a41844fc1709 | I20: S1A_IW_SLC__1SDV_20171029T113710_20171029T113739_019027_0202C9_66C0 | J20: MERIA global
A21: MARIDA | B21: marida_16pcc_20180830_05 | C21: 16PCC | D21: 2018-08-30 11:45:58 | E21: -4.372 | F21: 4.372 | G21: MARIDA | H21: marida_16PCC_2018-08-30 | I21: S1A_IW_SLC__1SDV_20180830T114558_20180830T114625_023475_028E42_5A19 | J21: MARIDA
A22: MARIDA | B22: marida_16pcc_20180830_05 | C22: 16PCC | D22: 2018-08-30 11:45:33 | E22: -4.379 | F22: 4.379 | G22: MARIDA | H22: marida_16PCC_2018-08-30 | I22: S1A_IW_SLC__1SDV_20180830T114533_20180830T114600_023475_028E42_1ED7 | J22: MARIDA
A23: MARIDA | B23: marida_51pts_20160716_01 | C23: 51PTS | D23: 2016-07-16 21:46:30 | E23: -4.495 | F23: 4.495 | G23: MARIDA | H23: marida_51PTS_2016-07-17 | I23: S1A_IW_SLC__1SDV_20160716T214630_20160716T214657_012179_012E3A_DCAE | J23: MARIDA
A24: MARIDA | B24: marida_18qyf_20210123_20210125_08 | C24: 18QYF | D24: 2021-01-23 10:47:29 | E24: -4.653 | F24: 4.653 | G24: MARIDA | H24: marida_18QYF_2021-01-23 | I24: S1A_IW_SLC__1SDV_20210123T104729_20210123T104755_036264_0440FD_9D34 | J24: MARIDA
... A142: South Africa | B142: sa_gqeberha_2024_jun20 | C142: Gqeberha | D142: 2024-06-20 17:01:42 | E142: 272.45 | F142: 272.45 | G142: MERIA SA | H142: MERIA_SA_008 | I142: S1A_IW_SLC__1SDV_20240620T170142_20240620T170210_054409_069EC5_00FD | J142: MERIA SA
